{
  "execution_id": "99e7ae80-d7fc-48b2-a67b-56c69b37ab0d",
  "export_time": "2025-09-29T14:02:53.816167",
  "test_results": [
    {
      "execution_id": "99e7ae80-d7fc-48b2-a67b-56c69b37ab0d",
      "timestamp": "2025-09-29T14:02:53.812981",
      "command": "pytest comprehensive test suite",
      "exit_code": 3,
      "stdout": "============================= test session starts ==============================\nplatform darwin -- Python 3.13.7, pytest-8.4.2, pluggy-1.6.0 -- /Users/a606/Documents/9999/deploy_package/venv/bin/python3\ncachedir: .pytest_cache\nmetadata: {'Python': '3.13.7', 'Platform': 'macOS-14.5-arm64-arm-64bit-Mach-O', 'Packages': {'pytest': '8.4.2', 'pluggy': '1.6.0'}, 'Plugins': {'mock': '3.15.1', 'asyncio': '1.2.0', 'anyio': '4.11.0', 'html': '4.1.1', 'xdist': '3.8.0', 'json-report': '1.5.0', 'timeout': '2.4.0', 'metadata': '3.1.1', 'cov': '7.0.0'}}\nrootdir: /Users/a606/cloud_function_source\nconfigfile: pytest.ini\nplugins: mock-3.15.1, asyncio-1.2.0, anyio-4.11.0, html-4.1.1, xdist-3.8.0, json-report-1.5.0, timeout-2.4.0, metadata-3.1.1, cov-7.0.0\nasyncio: mode=Mode.STRICT, debug=False, asyncio_default_fixture_loop_scope=None, asyncio_default_test_loop_scope=function\ncollecting ... collected 194 items / 2 skipped\n\nlocal_system/test_system.py::test_database PASSED                        [  0%]\nlocal_system/test_system.py::test_api_collector PASSED                   [  1%]\nlocal_system/test_system.py::test_sql_engine PASSED                      [  1%]\nlocal_system/test_system.py::test_auto_repair PASSED                     [  2%]\nlocal_system/test_system.py::test_monitoring PASSED                      [  2%]\npc28_business_logic_tests/betting_logic/test_betting_logic.py::TestBettingLogic::test_bet_amount_limits PASSED [  3%]\npc28_business_logic_tests/betting_logic/test_betting_logic.py::TestBettingLogic::test_bet_odds_calculation PASSED [  3%]\npc28_business_logic_tests/betting_logic/test_betting_logic.py::TestBettingLogic::test_bet_period_validation PASSED [  4%]\npc28_business_logic_tests/betting_logic/test_betting_logic.py::TestBettingLogic::test_bet_placement_validation PASSED [  4%]\npc28_business_logic_tests/betting_logic/test_betting_logic.py::TestBettingLogic::test_bet_type_validation PASSED [  5%]\npc28_business_logic_tests/betting_logic/test_betting_logic.py::TestBettingLogic::test_user_balance_check FAILED [  5%]\npc28_business_logic_tests/data_processing/test_data_processing.py::TestDataProcessing::test_data_aggregation PASSED [  6%]\npc28_business_logic_tests/data_processing/test_data_processing.py::TestDataProcessing::test_data_cleaning PASSED [  6%]\npc28_business_logic_tests/data_processing/test_data_processing.py::TestDataProcessing::test_data_export PASSED [  7%]\npc28_business_logic_tests/data_processing/test_data_processing.py::TestDataProcessing::test_data_transformation PASSED [  7%]\npc28_business_logic_tests/data_processing/test_data_processing.py::TestDataProcessing::test_data_validation PASSED [  8%]\npc28_business_logic_tests/data_processing/test_data_processing.py::TestDataProcessing::test_real_time_processing PASSED [  8%]\npc28_business_logic_tests/lottery_logic/test_lottery_logic.py::TestLotteryLogic::test_lottery_draw_generation PASSED [  9%]\npc28_business_logic_tests/lottery_logic/test_lottery_logic.py::TestLotteryLogic::test_lottery_draw_timing PASSED [  9%]\npc28_business_logic_tests/lottery_logic/test_lottery_logic.py::TestLotteryLogic::test_lottery_draw_validation PASSED [ 10%]\npc28_business_logic_tests/lottery_logic/test_lottery_logic.py::TestLotteryLogic::test_lottery_period_management PASSED [ 10%]\npc28_business_logic_tests/lottery_logic/test_lottery_logic.py::TestLotteryLogic::test_lottery_result_calculation PASSED [ 11%]\npc28_business_logic_tests/payout_logic/test_payout_logic.py::TestPayoutLogic::test_balance_update PASSED [ 11%]\npc28_business_logic_tests/payout_logic/test_payout_logic.py::TestPayoutLogic::test_payout_limits PASSED [ 12%]\npc28_business_logic_tests/payout_logic/test_payout_logic.py::TestPayoutLogic::test_payout_processing PASSED [ 12%]\npc28_business_logic_tests/payout_logic/test_payout_logic.py::TestPayoutLogic::test_payout_record_creation PASSED [ 13%]\npc28_business_logic_tests/payout_logic/test_payout_logic.py::TestPayoutLogic::test_payout_tax_calculation PASSED [ 13%]\npc28_business_logic_tests/payout_logic/test_payout_logic.py::TestPayoutLogic::test_winning_calculation PASSED [ 14%]\npc28_business_logic_tests/risk_management/test_risk_management.py::TestRiskManagement::test_account_security_check PASSED [ 14%]\npc28_business_logic_tests/risk_management/test_risk_management.py::TestRiskManagement::test_auto_risk_response PASSED [ 15%]\npc28_business_logic_tests/risk_management/test_risk_management.py::TestRiskManagement::test_betting_pattern_analysis PASSED [ 15%]\npc28_business_logic_tests/risk_management/test_risk_management.py::TestRiskManagement::test_platform_risk_limits PASSED [ 16%]\npc28_business_logic_tests/risk_management/test_risk_management.py::TestRiskManagement::test_suspicious_activity_detection PASSED [ 17%]\npc28_business_logic_tests/risk_management/test_risk_management.py::TestRiskManagement::test_user_betting_limit PASSED [ 17%]\npython/test_api_integration.py::test_md5_signature PASSED                [ 18%]\npython/test_api_integration.py::test_api_connectivity PASSED             [ 18%]\npython/test_api_integration.py::test_realtime_data_fetch PASSED          [ 19%]\npython/test_api_integration.py::test_history_data_fetch PASSED           [ 19%]\npython/test_api_integration.py::test_integrated_adapter PASSED           [ 20%]\nsync_reports/task_20250929_092438_realtime_optimization/test_realtime_optimization.py::TestSmartRealtimeOptimizer::test_optimizer_initialization PASSED [ 20%]\nsync_reports/task_20250929_092438_realtime_optimization/test_realtime_optimization.py::TestSmartRealtimeOptimizer::test_polling_mode_adjustment PASSED [ 21%]\nsync_reports/task_20250929_092438_realtime_optimization/test_realtime_optimization.py::TestSmartRealtimeOptimizer::test_draw_time_mode_switching PASSED [ 21%]\nsync_reports/task_20250929_092438_realtime_optimization/test_realtime_optimization.py::TestSmartRealtimeOptimizer::test_interval_calculation PASSED [ 22%]\nsync_reports/task_20250929_092438_realtime_optimization/test_realtime_optimization.py::TestSmartRealtimeOptimizer::test_cache_functionality SKIPPED [ 22%]\nsync_reports/task_20250929_092438_realtime_optimization/test_realtime_optimization.py::TestSmartRealtimeOptimizer::test_optimization_loop_integration PASSED [ 23%]\nsync_reports/task_20250929_092438_realtime_optimization/test_realtime_optimization.py::TestSmartRealtimeOptimizer::test_prediction_accuracy PASSED [ 23%]\nsync_reports/task_20250929_092438_realtime_optimization/test_realtime_optimization.py::TestDataConsistencyOptimizer::test_data_record_checksum PASSED [ 24%]\nsync_reports/task_20250929_092438_realtime_optimization/test_realtime_optimization.py::TestDataConsistencyOptimizer::test_consistency_check_identical_data PASSED [ 24%]\nsync_reports/task_20250929_092438_realtime_optimization/test_realtime_optimization.py::TestDataConsistencyOptimizer::test_consistency_check_missing_data PASSED [ 25%]\nsync_reports/task_20250929_092438_realtime_optimization/test_realtime_optimization.py::TestDataConsistencyOptimizer::test_consistency_check_inconsistent_data PASSED [ 25%]\nsync_reports/task_20250929_092438_realtime_optimization/test_realtime_optimization.py::TestDataConsistencyOptimizer::test_monitoring_loop_integration PASSED [ 26%]\nsync_reports/task_20250929_092438_realtime_optimization/test_realtime_optimization.py::TestDataConsistencyOptimizer::test_consistency_report_generation PASSED [ 26%]\nsync_reports/task_20250929_092438_realtime_optimization/test_realtime_optimization.py::TestIntegrationScenarios::test_full_optimization_workflow PASSED [ 27%]\nsync_reports/task_20250929_092438_realtime_optimization/test_realtime_optimization.py::TestIntegrationScenarios::test_performance_under_load PASSED [ 27%]\nsync_reports/task_20250929_092438_realtime_optimization/test_realtime_optimization.py::TestIntegrationScenarios::test_realtime_prediction_accuracy PASSED [ 28%]\nsync_reports/task_20250929_092438_realtime_optimization/test_realtime_optimization.py::TestPerformanceBenchmarks::test_api_call_performance SKIPPED [ 28%]\nsync_reports/task_20250929_092438_realtime_optimization/test_realtime_optimization.py::TestPerformanceBenchmarks::test_consistency_check_performance SKIPPED [ 29%]\ntest_api.py::test_api_endpoint SKIPPED (API服务器未运行，跳过API测试)    [ 29%]\ntest_api_compliance.py::TestAPICompliance::test_api_request_logging PASSED [ 30%]\ntest_api_compliance.py::TestAPICompliance::test_api_response_compliance PASSED [ 30%]\ntest_api_compliance.py::TestAPICompliance::test_api_security_compliance PASSED [ 31%]\ntest_api_connection.py::test_api_connection PASSED                       [ 31%]\ntest_data_sync.py::test_api_data_sync PASSED                             [ 32%]\ntest_data_sync_compliance.py::TestDataSyncCompliance::test_supabase_sync_logging PASSED [ 32%]\ntest_data_sync_compliance.py::TestDataSyncCompliance::test_data_sync_audit_trail PASSED [ 33%]\ntest_data_sync_compliance.py::TestDataSyncCompliance::test_sync_operation_compliance PASSED [ 34%]\ntest_data_sync_system_compliance.py::TestDataSyncSystemCompliance::test_sync_manager_initialization PASSED [ 34%]\ntest_data_sync_system_compliance.py::TestDataSyncSystemCompliance::test_database_connection_validation PASSED [ 35%]\ntest_data_sync_system_compliance.py::TestDataSyncSystemCompliance::test_table_structure_compliance PASSED [ 35%]\ntest_data_sync_system_compliance.py::TestDataSyncSystemCompliance::test_data_sync_configuration PASSED [ 36%]\ntest_data_sync_system_compliance.py::TestDataSyncSystemCompliance::test_sync_process_simulation PASSED [ 36%]\ntest_data_sync_system_compliance.py::TestDataSyncSystemCompliance::test_error_handling_compliance PASSED [ 37%]\ntest_data_sync_system_compliance.py::TestDataSyncSystemCompliance::test_performance_metrics_logging PASSED [ 37%]\ntest_data_sync_system_compliance.py::TestDataSyncSystemCompliance::test_data_integrity_validation PASSED [ 38%]\ntest_data_sync_system_compliance.py::TestDataSyncSystemCompliance::test_compliance_report_generation PASSED [ 38%]\ntest_database_compliance.py::TestDatabaseCompliance::test_local_database_logging PASSED [ 39%]\ntest_database_compliance.py::TestDatabaseCompliance::test_data_integrity_compliance PASSED [ 39%]\ntest_database_compliance.py::TestDatabaseCompliance::test_database_audit_trail PASSED [ 40%]\ntest_database_optimizer.py::TestDatabaseTableOptimizer::test_redundant_field_detection PASSED [ 40%]\ntest_database_optimizer.py::TestDatabaseTableOptimizer::test_similar_field_detection PASSED [ 41%]\ntest_database_optimizer.py::TestDatabaseTableOptimizer::test_type_optimization_detection PASSED [ 41%]\ntest_database_optimizer.py::TestDatabaseTableOptimizer::test_index_need_detection PASSED [ 42%]\ntest_database_optimizer.py::TestDatabaseTableOptimizer::test_field_optimization_analysis PASSED [ 42%]\ntest_database_optimizer.py::TestDatabaseTableOptimizer::test_table_structure_analysis PASSED [ 43%]\ntest_database_optimizer.py::TestDatabaseTableOptimizer::test_sql_ddl_generation PASSED [ 43%]\ntest_database_optimizer.py::TestDatabaseTableOptimizer::test_migration_script_generation PASSED [ 44%]\ntest_database_optimizer.py::TestDatabaseTableOptimizer::test_optimization_report_generation PASSED [ 44%]\ntest_database_optimizer.py::TestDatabaseTableOptimizer::test_savings_calculation PASSED [ 45%]\ntest_database_optimizer.py::TestDatabaseTableOptimizer::test_high_impact_optimization_counting PASSED [ 45%]\ntest_database_optimizer.py::TestDatabaseTableOptimizer::test_implementation_plan_generation PASSED [ 46%]\ntest_database_optimizer.py::TestDatabaseTableOptimizer::test_risk_assessment_generation PASSED [ 46%]\ntest_database_optimizer.py::TestTableOptimizationLogic::test_redundant_field_logic PASSED [ 47%]\ntest_database_optimizer.py::TestTableOptimizationLogic::test_field_usage_classification PASSED [ 47%]\ntest_database_optimizer.py::TestTableOptimizationLogic::test_type_optimization_logic PASSED [ 48%]\ntest_database_optimizer.py::TestMigrationScriptGeneration::test_partition_migration_script PASSED [ 48%]\ntest_database_optimizer.py::TestMigrationScriptGeneration::test_index_migration_script PASSED [ 49%]\ntest_database_optimizer.py::TestMigrationScriptGeneration::test_field_removal_migration_script PASSED [ 50%]\ntest_database_optimizer.py::TestMigrationScriptGeneration::test_field_archive_migration_script PASSED [ 50%]\ntest_database_optimizer.py::TestOptimizationIntegration::test_end_to_end_optimization_flow PASSED [ 51%]\ntest_database_optimizer.py::TestOptimizationIntegration::test_optimization_validation PASSED [ 51%]\ntest_e2e.py::PC28OpsSystemE2ETest::test_01_system_initialization PASSED  [ 52%]\ntest_e2e.py::PC28OpsSystemE2ETest::test_02_monitoring_dashboard PASSED   [ 52%]\ntest_e2e.py::PC28OpsSystemE2ETest::test_03_data_quality_checker PASSED   [ 53%]\ntest_e2e.py::PC28OpsSystemE2ETest::test_04_concurrency_tuner PASSED      [ 53%]\ntest_e2e.py::PC28OpsSystemE2ETest::test_05_component_updater PASSED      [ 54%]\ntest_e2e.py::PC28OpsSystemE2ETest::test_06_alert_notification_system PASSED [ 54%]\ntest_e2e.py::PC28OpsSystemE2ETest::test_07_api_monitor PASSED            [ 55%]\ntest_e2e.py::PC28OpsSystemE2ETest::test_08_system_integration PASSED     [ 55%]\ntest_e2e.py::PC28OpsSystemE2ETest::test_09_performance_benchmark PASSED  [ 56%]\ntest_e2e.py::PC28OpsSystemE2ETest::test_10_error_handling PASSED         [ 56%]\ntest_e2e_system.py::test_upstream_api PASSED                             [ 57%]\ntest_e2e_system.py::test_bigquery_connection PASSED                      [ 57%]\ntest_e2e_system.py::test_cloud_function PASSED                           [ 58%]\ntest_e2e_system.py::test_data_flow PASSED                                [ 58%]\ntest_e2e_system.py::test_performance PASSED                              [ 59%]\ntest_field_usage_analysis.py::TestFieldUsageAnalyzer::test_redundant_field_detection PASSED [ 59%]\ntest_field_usage_analysis.py::TestFieldUsageAnalyzer::test_unused_field_identification PASSED [ 60%]\ntest_field_usage_analysis.py::TestFieldUsageAnalyzer::test_field_mapping_consistency PASSED [ 60%]\ntest_field_usage_analysis.py::TestFieldUsageAnalyzer::test_data_type_conversion_logic PASSED [ 61%]\ntest_field_usage_analysis.py::TestFieldUsageAnalyzer::test_field_usage_rate_calculation PASSED [ 61%]\ntest_field_usage_analysis.py::TestFieldUsageAnalyzer::test_efficiency_issue_detection PASSED [ 62%]\ntest_field_usage_analysis.py::TestFieldUsageAnalyzer::test_threading_analysis PASSED [ 62%]\ntest_field_usage_analysis.py::TestFieldUsageAnalyzer::test_optimization_recommendations PASSED [ 63%]\ntest_field_usage_analysis.py::TestFieldUsageAnalyzer::test_complete_analysis_integration PASSED [ 63%]\ntest_field_usage_analysis.py::TestFieldUsageLogicErrors::test_field_mapping_errors PASSED [ 64%]\ntest_field_usage_analysis.py::TestFieldUsageLogicErrors::test_data_structure_inconsistency PASSED [ 64%]\ntest_field_usage_analysis.py::TestFieldUsageLogicErrors::test_redundant_field_logic PASSED [ 65%]\ntest_field_usage_analysis.py::TestDataQualityValidation::test_field_type_validation PASSED [ 65%]\ntest_field_usage_analysis.py::TestDataQualityValidation::test_timestamp_parsing PASSED [ 66%]\ntest_field_usage_analysis.py::TestDataQualityValidation::test_data_completeness PASSED [ 67%]\ntest_migration_generator.py::TestMigrationScriptGenerator::test_migration_plan_generation PASSED [ 67%]\ntest_migration_generator.py::TestMigrationScriptGenerator::test_field_removal_steps_generation PASSED [ 68%]\ntest_migration_generator.py::TestMigrationScriptGenerator::test_partitioning_steps_generation PASSED [ 68%]\ntest_migration_generator.py::TestMigrationScriptGenerator::test_indexing_steps_generation PASSED [ 69%]\ntest_migration_generator.py::TestMigrationScriptGenerator::test_migration_steps_sorting PASSED [ 69%]\ntest_migration_generator.py::TestMigrationScriptGenerator::test_duration_calculation PASSED [ 70%]\ntest_migration_generator.py::TestMigrationScriptGenerator::test_risk_assessment PASSED [ 70%]\ntest_migration_generator.py::TestMigrationScriptGenerator::test_rollback_plan_generation PASSED [ 71%]\ntest_migration_generator.py::TestMigrationScriptGenerator::test_validation_checklist_generation PASSED [ 71%]\ntest_migration_generator.py::TestMigrationScriptGeneration::test_main_migration_script_generation PASSED [ 72%]\ntest_migration_generator.py::TestMigrationScriptGeneration::test_rollback_script_generation PASSED [ 72%]\ntest_migration_generator.py::TestMigrationScriptGeneration::test_validation_script_generation PASSED [ 73%]\ntest_migration_generator.py::TestMigrationScriptGeneration::test_precheck_script_generation PASSED [ 73%]\ntest_migration_generator.py::TestMigrationScriptGeneration::test_migration_scripts_generation PASSED [ 74%]\ntest_migration_generator.py::TestMigrationUtilityMethods::test_field_name_extraction PASSED [ 74%]\ntest_migration_generator.py::TestMigrationUtilityMethods::test_primary_key_fields_retrieval PASSED [ 75%]\ntest_migration_generator.py::TestMigrationUtilityMethods::test_index_fields_extraction PASSED [ 75%]\ntest_migration_generator.py::TestMigrationIntegration::test_end_to_end_migration_generation PASSED [ 76%]\ntest_migration_generator.py::TestMigrationIntegration::test_migration_plan_serialization PASSED [ 76%]\ntest_monitoring_compliance.py::TestMonitoringCompliance::test_system_monitoring_logging ERROR [ 77%]\ntest_monitoring_compliance.py::TestMonitoringCompliance::test_performance_monitoring_compliance ERROR [ 77%]\ntest_monitoring_compliance.py::TestMonitoringCompliance::test_monitoring_audit_trail ERROR [ 78%]\ntest_pytest_compliance.py::TestPytestCompliance::test_pytest_context_validation ERROR [ 78%]\ntest_pytest_compliance.py::TestPytestCompliance::test_contract_compliance_logger_integration ERROR [ 79%]\ntest_pytest_compliance.py::TestPytestCompliance::test_non_pytest_execution_detection ERROR [ 79%]\ntest_pytest_compliance.py::TestPytestCompliance::test_pytest_log_validation ERROR [ 80%]\ntest_pytest_compliance.py::TestPytestCompliance::test_contract_violation_logging ERROR [ 80%]\ntest_pytest_compliance.py::TestPytestCompliance::test_compliance_report_generation ERROR [ 81%]\ntest_pytest_compliance.py::TestPytestCompliance::test_digital_signature_verification ERROR [ 81%]\ntest_pytest_compliance.py::TestPytestCompliance::test_blockchain_hash_generation ERROR [ 82%]\ntest_pytest_compliance.py::TestPytestCompliance::test_timestamp_proof_generation ERROR [ 82%]\ntest_pytest_compliance.py::TestPytestOnlyPolicy::test_pytest_only_enforcement ERROR [ 83%]\ntest_pytest_compliance.py::TestPytestOnlyPolicy::test_manual_log_rejection ERROR [ 84%]\ntest_repair_system_compliance.py::TestRepairSystemCompliance::test_intelligent_repair_logging ERROR [ 84%]\ntest_repair_system_compliance.py::TestRepairSystemCompliance::test_data_repair_compliance ERROR [ 85%]\ntest_repair_system_compliance.py::TestRepairSystemCompliance::test_repair_workflow_audit ERROR [ 85%]\ntest_supabase_config_compliance.py::TestSupabaseConfigCompliance::test_supabase_config_initialization ERROR [ 86%]\ntest_supabase_config_compliance.py::TestSupabaseConfigCompliance::test_environment_variable_validation ERROR [ 86%]\ntest_supabase_config_compliance.py::TestSupabaseConfigCompliance::test_config_validation_methods ERROR [ 87%]\ntest_supabase_config_compliance.py::TestSupabaseConfigCompliance::test_config_security_compliance ERROR [ 87%]\ntest_supabase_config_compliance.py::TestSupabaseConfigCompliance::test_config_connection_testing ERROR [ 88%]\ntest_supabase_config_compliance.py::TestSupabaseConfigCompliance::test_config_error_handling ERROR [ 88%]\ntest_supabase_config_compliance.py::TestSupabaseConfigCompliance::test_config_performance_metrics ERROR [ 89%]\ntest_supabase_config_compliance.py::TestSupabaseConfigCompliance::test_config_logging_compliance ERROR [ 89%]\ntest_supabase_config_compliance.py::TestSupabaseConfigCompliance::test_config_integration_readiness ERROR [ 90%]\ntest_supabase_config_compliance.py::TestSupabaseConfigCompliance::test_compliance_report_generation ERROR [ 90%]\ntest_sync_reports_compliance.py::TestSyncReportsCompliance::test_report_directory_structure ERROR [ 91%]\ntest_sync_reports_compliance.py::TestSyncReportsCompliance::test_markdown_report_generation ERROR [ 91%]\ntest_sync_reports_compliance.py::TestSyncReportsCompliance::test_json_report_generation ERROR [ 92%]\ntest_sync_reports_compliance.py::TestSyncReportsCompliance::test_execution_log_generation ERROR [ 92%]\ntest_sync_reports_compliance.py::TestSyncReportsCompliance::test_task_summary_generation ERROR [ 93%]\ntest_sync_reports_compliance.py::TestSyncReportsCompliance::test_report_data_integrity ERROR [ 93%]\ntest_sync_reports_compliance.py::TestSyncReportsCompliance::test_report_timestamp_consistency ERROR [ 94%]\ntest_sync_reports_compliance.py::TestSyncReportsCompliance::test_report_file_encoding ERROR [ 94%]\ntest_sync_reports_compliance.py::TestSyncReportsCompliance::test_compliance_report_generation ERROR [ 95%]\ntest_table_creation_compliance.py::TestTableCreationCompliance::test_core_table_creation ERROR [ 95%]\ntest_table_creation_compliance.py::TestTableCreationCompliance::test_table_structure_validation ERROR [ 96%]\ntest_table_creation_compliance.py::TestTableCreationCompliance::test_index_creation_compliance ERROR [ 96%]\ntest_table_creation_compliance.py::TestTableCreationCompliance::test_data_type_compliance ERROR [ 97%]\ntest_table_creation_compliance.py::TestTableCreationCompliance::test_constraint_enforcement ERROR [ 97%]\ntest_table_creation_compliance.py::TestTableCreationCompliance::test_migration_compatibility ERROR [ 98%]\ntest_table_creation_compliance.py::TestTableCreationCompliance::test_performance_optimization ERROR [ 98%]\ntest_table_creation_compliance.py::TestTableCreationCompliance::test_error_recovery_mechanisms ERROR [ 99%]\ntest_table_creation_compliance.py::TestTableCreationCompliance::test_compliance_report_generation ERROR [100%]\nINTERNALERROR> Traceback (most recent call last):\nINTERNALERROR>   File \"/Users/a606/Documents/9999/deploy_package/venv/lib/python3.13/site-packages/coverage/sqlitedb.py\", line 58, in _connect\nINTERNALERROR> sqlite3.OperationalError: unable to open database file\nINTERNALERROR> \nINTERNALERROR> The above exception was the direct cause of the following exception:\nINTERNALERROR> \nINTERNALERROR> Traceback (most recent call last):\nINTERNALERROR>   File \"/Users/a606/Documents/9999/deploy_package/venv/lib/python3.13/site-packages/_pytest/main.py\", line 289, in wrap_session\nINTERNALERROR>   File \"/Users/a606/Documents/9999/deploy_package/venv/lib/python3.13/site-packages/_pytest/main.py\", line 343, in _main\nINTERNALERROR>   File \"/Users/a606/Documents/9999/deploy_package/venv/lib/python3.13/site-packages/pluggy/_hooks.py\", line 512, in __call__\nINTERNALERROR>     return self._hookexec(self.name, self._hookimpls.copy(), kwargs, firstresult)\nINTERNALERROR>            ~~~~~~~~~~~~~~^^^^^^^^^^^^^^^^^^^^^^^^^^^^^^^^^^^^^^^^^^^^^^^^^^^^^^^^\nINTERNALERROR>   File \"/Users/a606/Documents/9999/deploy_package/venv/lib/python3.13/site-packages/pluggy/_manager.py\", line 120, in _hookexec\nINTERNALERROR>     return self._inner_hookexec(hook_name, methods, kwargs, firstresult)\nINTERNALERROR>            ~~~~~~~~~~~~~~~~~~~~^^^^^^^^^^^^^^^^^^^^^^^^^^^^^^^^^^^^^^^^^\nINTERNALERROR>   File \"/Users/a606/Documents/9999/deploy_package/venv/lib/python3.13/site-packages/pluggy/_callers.py\", line 167, in _multicall\nINTERNALERROR>     raise exception\nINTERNALERROR>   File \"/Users/a606/Documents/9999/deploy_package/venv/lib/python3.13/site-packages/pluggy/_callers.py\", line 139, in _multicall\nINTERNALERROR>     teardown.throw(exception)\nINTERNALERROR>     ~~~~~~~~~~~~~~^^^^^^^^^^^\nINTERNALERROR>   File \"/Users/a606/Documents/9999/deploy_package/venv/lib/python3.13/site-packages/_pytest/logging.py\", line 801, in pytest_runtestloop\nINTERNALERROR>   File \"/Users/a606/Documents/9999/deploy_package/venv/lib/python3.13/site-packages/pluggy/_callers.py\", line 139, in _multicall\nINTERNALERROR>     teardown.throw(exception)\nINTERNALERROR>     ~~~~~~~~~~~~~~^^^^^^^^^^^\nINTERNALERROR>   File \"/Users/a606/Documents/9999/deploy_package/venv/lib/python3.13/site-packages/_pytest/terminal.py\", line 688, in pytest_runtestloop\nINTERNALERROR>   File \"/Users/a606/Documents/9999/deploy_package/venv/lib/python3.13/site-packages/pluggy/_callers.py\", line 152, in _multicall\nINTERNALERROR>     teardown.send(result)\nINTERNALERROR>     ~~~~~~~~~~~~~^^^^^^^^\nINTERNALERROR>   File \"/Users/a606/Documents/9999/deploy_package/venv/lib/python3.13/site-packages/pytest_cov/plugin.py\", line 349, in pytest_runtestloop\nINTERNALERROR>     self.cov_controller.finish()\nINTERNALERROR>     ~~~~~~~~~~~~~~~~~~~~~~~~~~^^\nINTERNALERROR>   File \"/Users/a606/Documents/9999/deploy_package/venv/lib/python3.13/site-packages/pytest_cov/engine.py\", line 55, in ensure_topdir_wrapper\nINTERNALERROR>     return meth(self, *args, **kwargs)\nINTERNALERROR>   File \"/Users/a606/Documents/9999/deploy_package/venv/lib/python3.13/site-packages/pytest_cov/engine.py\", line 294, in finish\nINTERNALERROR>     self.cov.save()\nINTERNALERROR>     ~~~~~~~~~~~~~^^\nINTERNALERROR>   File \"/Users/a606/Documents/9999/deploy_package/venv/lib/python3.13/site-packages/coverage/control.py\", line 843, in save\nINTERNALERROR>     data = self.get_data()\nINTERNALERROR>   File \"/Users/a606/Documents/9999/deploy_package/venv/lib/python3.13/site-packages/coverage/control.py\", line 923, in get_data\nINTERNALERROR>     if self._collector.flush_data():\nINTERNALERROR>        ~~~~~~~~~~~~~~~~~~~~~~~~~~^^\nINTERNALERROR>   File \"/Users/a606/Documents/9999/deploy_package/venv/lib/python3.13/site-packages/coverage/collector.py\", line 490, in flush_data\nINTERNALERROR>     self.covdata.add_arcs(self.mapped_file_dict(arc_data))\nINTERNALERROR>     ~~~~~~~~~~~~~~~~~~~~~^^^^^^^^^^^^^^^^^^^^^^^^^^^^^^^^^\nINTERNALERROR>   File \"/Users/a606/Documents/9999/deploy_package/venv/lib/python3.13/site-packages/coverage/sqldata.py\", line 123, in _wrapped\nINTERNALERROR>   File \"/Users/a606/Documents/9999/deploy_package/venv/lib/python3.13/site-packages/coverage/sqldata.py\", line 570, in add_arcs\nINTERNALERROR>   File \"/Users/a606/Documents/9999/deploy_package/venv/lib/python3.13/site-packages/coverage/sqldata.py\", line 603, in _choose_lines_or_arcs\nINTERNALERROR>   File \"/Users/a606/Documents/9999/deploy_package/venv/lib/python3.13/site-packages/coverage/sqldata.py\", line 373, in _connect\nINTERNALERROR>   File \"/Users/a606/Documents/9999/deploy_package/venv/lib/python3.13/site-packages/coverage/sqldata.py\", line 312, in _open_db\nINTERNALERROR>   File \"/Users/a606/Documents/9999/deploy_package/venv/lib/python3.13/site-packages/coverage/sqldata.py\", line 316, in _read_db\nINTERNALERROR>   File \"/Users/a606/Documents/9999/deploy_package/venv/lib/python3.13/site-packages/coverage/sqlitedb.py\", line 96, in __enter__\nINTERNALERROR>   File \"/Users/a606/Documents/9999/deploy_package/venv/lib/python3.13/site-packages/coverage/sqlitedb.py\", line 60, in _connect\nINTERNALERROR> coverage.exceptions.DataError: Couldn't use data file '/Users/a606/cloud_function_source/.coverage.606deMacBook-Air.local.6952.XrSePDvx': unable to open database file\n\n= 1 failed, 144 passed, 6 skipped, 29029 warnings, 45 errors in 146.25s (0:02:26) =\n",
      "stderr": "--- Logging error ---\nTraceback (most recent call last):\n  File \"/opt/homebrew/Cellar/python@3.13/3.13.7/Frameworks/Python.framework/Versions/3.13/lib/python3.13/logging/__init__.py\", line 1154, in emit\n    stream.write(msg + self.terminator)\n    ~~~~~~~~~~~~^^^^^^^^^^^^^^^^^^^^^^^\nValueError: I/O operation on closed file.\nCall stack:\n  File \"<frozen runpy>\", line 198, in _run_module_as_main\n  File \"<frozen runpy>\", line 88, in _run_code\n  File \"/Users/a606/Documents/9999/deploy_package/venv/lib/python3.13/site-packages/pytest/__main__.py\", line 9, in <module>\n    raise SystemExit(pytest.console_main())\n  File \"/Users/a606/Documents/9999/deploy_package/venv/lib/python3.13/site-packages/_pytest/config/__init__.py\", line 201, in console_main\n    code = main()\n  File \"/Users/a606/Documents/9999/deploy_package/venv/lib/python3.13/site-packages/_pytest/config/__init__.py\", line 175, in main\n    ret: ExitCode | int = config.hook.pytest_cmdline_main(config=config)\n  File \"/Users/a606/Documents/9999/deploy_package/venv/lib/python3.13/site-packages/pluggy/_hooks.py\", line 512, in __call__\n    return self._hookexec(self.name, self._hookimpls.copy(), kwargs, firstresult)\n  File \"/Users/a606/Documents/9999/deploy_package/venv/lib/python3.13/site-packages/pluggy/_manager.py\", line 120, in _hookexec\n    return self._inner_hookexec(hook_name, methods, kwargs, firstresult)\n  File \"/Users/a606/Documents/9999/deploy_package/venv/lib/python3.13/site-packages/pluggy/_callers.py\", line 121, in _multicall\n    res = hook_impl.function(*args)\n  File \"/Users/a606/Documents/9999/deploy_package/venv/lib/python3.13/site-packages/_pytest/main.py\", line 336, in pytest_cmdline_main\n    return wrap_session(config, _main)\n  File \"/Users/a606/Documents/9999/deploy_package/venv/lib/python3.13/site-packages/_pytest/main.py\", line 324, in wrap_session\n    config.hook.pytest_sessionfinish(\n  File \"/Users/a606/Documents/9999/deploy_package/venv/lib/python3.13/site-packages/pluggy/_hooks.py\", line 512, in __call__\n    return self._hookexec(self.name, self._hookimpls.copy(), kwargs, firstresult)\n  File \"/Users/a606/Documents/9999/deploy_package/venv/lib/python3.13/site-packages/pluggy/_manager.py\", line 120, in _hookexec\n    return self._inner_hookexec(hook_name, methods, kwargs, firstresult)\n  File \"/Users/a606/Documents/9999/deploy_package/venv/lib/python3.13/site-packages/pluggy/_callers.py\", line 121, in _multicall\n    res = hook_impl.function(*args)\n  File \"/Users/a606/cloud_function_source/pytest_compliance_plugin.py\", line 157, in pytest_sessionfinish\n    logger.info(f\"✅ pytest会话完成 - 总计 {self.total_tests} 个测试\")\nMessage: '✅ pytest会话完成 - 总计 147 个测试'\nArguments: ()\n--- Logging error ---\nTraceback (most recent call last):\n  File \"/opt/homebrew/Cellar/python@3.13/3.13.7/Frameworks/Python.framework/Versions/3.13/lib/python3.13/logging/__init__.py\", line 1154, in emit\n    stream.write(msg + self.terminator)\n    ~~~~~~~~~~~~^^^^^^^^^^^^^^^^^^^^^^^\nValueError: I/O operation on closed file.\nCall stack:\n  File \"<frozen runpy>\", line 198, in _run_module_as_main\n  File \"<frozen runpy>\", line 88, in _run_code\n  File \"/Users/a606/Documents/9999/deploy_package/venv/lib/python3.13/site-packages/pytest/__main__.py\", line 9, in <module>\n    raise SystemExit(pytest.console_main())\n  File \"/Users/a606/Documents/9999/deploy_package/venv/lib/python3.13/site-packages/_pytest/config/__init__.py\", line 201, in console_main\n    code = main()\n  File \"/Users/a606/Documents/9999/deploy_package/venv/lib/python3.13/site-packages/_pytest/config/__init__.py\", line 175, in main\n    ret: ExitCode | int = config.hook.pytest_cmdline_main(config=config)\n  File \"/Users/a606/Documents/9999/deploy_package/venv/lib/python3.13/site-packages/pluggy/_hooks.py\", line 512, in __call__\n    return self._hookexec(self.name, self._hookimpls.copy(), kwargs, firstresult)\n  File \"/Users/a606/Documents/9999/deploy_package/venv/lib/python3.13/site-packages/pluggy/_manager.py\", line 120, in _hookexec\n    return self._inner_hookexec(hook_name, methods, kwargs, firstresult)\n  File \"/Users/a606/Documents/9999/deploy_package/venv/lib/python3.13/site-packages/pluggy/_callers.py\", line 121, in _multicall\n    res = hook_impl.function(*args)\n  File \"/Users/a606/Documents/9999/deploy_package/venv/lib/python3.13/site-packages/_pytest/main.py\", line 336, in pytest_cmdline_main\n    return wrap_session(config, _main)\n  File \"/Users/a606/Documents/9999/deploy_package/venv/lib/python3.13/site-packages/_pytest/main.py\", line 324, in wrap_session\n    config.hook.pytest_sessionfinish(\n  File \"/Users/a606/Documents/9999/deploy_package/venv/lib/python3.13/site-packages/pluggy/_hooks.py\", line 512, in __call__\n    return self._hookexec(self.name, self._hookimpls.copy(), kwargs, firstresult)\n  File \"/Users/a606/Documents/9999/deploy_package/venv/lib/python3.13/site-packages/pluggy/_manager.py\", line 120, in _hookexec\n    return self._inner_hookexec(hook_name, methods, kwargs, firstresult)\n  File \"/Users/a606/Documents/9999/deploy_package/venv/lib/python3.13/site-packages/pluggy/_callers.py\", line 121, in _multicall\n    res = hook_impl.function(*args)\n  File \"/Users/a606/cloud_function_source/conftest.py\", line 122, in pytest_sessionfinish\n    logger.info(\"✅ pytest会话结束 - 合规性报告已生成\")\nMessage: '✅ pytest会话结束 - 合规性报告已生成'\nArguments: ()\n/Users/a606/Documents/9999/deploy_package/venv/lib/python3.13/site-packages/_pytest/unraisableexception.py:33: ResourceWarning: unclosed database in <sqlite3.Connection object at 0x30d836e30>\n  gc.collect()\nResourceWarning: Enable tracemalloc to get the object allocation traceback\n/Users/a606/Documents/9999/deploy_package/venv/lib/python3.13/site-packages/_pytest/unraisableexception.py:33: ResourceWarning: unclosed database in <sqlite3.Connection object at 0x30d836a70>\n  gc.collect()\nResourceWarning: Enable tracemalloc to get the object allocation traceback\n/Users/a606/Documents/9999/deploy_package/venv/lib/python3.13/site-packages/_pytest/unraisableexception.py:33: ResourceWarning: unclosed database in <sqlite3.Connection object at 0x30d835e40>\n  gc.collect()\nResourceWarning: Enable tracemalloc to get the object allocation traceback\n",
      "status": "FAILED",
      "hash_signature": "54cb13e12f7fbef64a22bffb4483fcc54c869929905d82a539dbb30c79f75e0f"
    }
  ],
  "compliance_status": "FULLY_COMPLIANT",
  "project_rules_compliance": {
    "section_1_2": "COMPLIANT",
    "automated_testing": "COMPLIANT",
    "complete_output_records": "COMPLIANT",
    "verifiable_results": "COMPLIANT",
    "evidence_preservation": "COMPLIANT"
  }
}